<?xml version="1.0"?>
<robot xmlns:xacro="http://www.ros.org/wiki/xacro" name="khaled_robot">


    <xacro:include filename="$(find differential_drive_robot)/urdf/2d_lidar.xacro"/>
    <xacro:include filename="$(find differential_drive_robot)/urdf/ultrasonic.xacro"/>
    <xacro:include filename="$(find differential_drive_robot)/urdf/imu.xacro"/>
    <!-- <xacro:include filename="$(find differential_drive_robot)/urdf/3d_lider.xacro"/> -->
    <!-- <xacro:include filename="$(find differential_drive_robot)/urdf/mono_camera.xacro"/> -->
    <xacro:include filename="$(find differential_drive_robot)/urdf/_d435.urdf.xacro"/>

    <xacro:sensor_d435 parent="base_link" use_nominal_extrinsics="true">
      <origin xyz="0.19 0 0.04" rpy="0 0 0"/>
    </xacro:sensor_d435>


    <!-- base link -->
    <link name="base_link">
        <inertial>
            <origin xyz="0.0 0.0 0.0" rpy="0.0 0.0 0.0"/>
            <mass value="0.2"/>
            <inertia ixx="0.0" ixy="0.0" ixz="0.0" iyy="0.0" iyz="0.0" izz="0.0"/>
        </inertial>
        <visual name="">
            <origin xyz="0.0 0.0 0.0" rpy="0.0 0.0 0.0"/>
            <geometry>
                <box size="0.4 0.3 0.08"/>
            </geometry>
            <material name="base_link_material">
                <color rgba="1.0 1.0 0.0 1.0"/>
                <texture filename=""/>
            </material>
        </visual>
        <collision>
            <origin xyz="0.0 0.0 0.0" rpy="0.0 0.0 0.0"/>
            <geometry>
                <box size="0.4 0.3 0.08"/>
            </geometry>
        </collision>
    </link>

    <!-- right wheel link -->
    <link name="right_wheel">
        <inertial>
            <origin xyz="0.0 0.0 0.0" rpy="0.0 0.0 0.0"/>
            <mass value="0.05"/>
            <inertia ixx="0.001" ixy="0.0" ixz="0.0" iyy="0.001" iyz="0.0" izz="0.001"/>
        </inertial>
        <visual name="">
            <origin xyz="0.0 0.0 0.0" rpy="0.0 0.0 0.0"/>
            <geometry>
                <cylinder radius="0.08" length="0.05"/>
            </geometry>
            <material name="">
                <color rgba="1.0 0.0 0.0 1.0"/>
                <texture filename=""/>
            </material>
        </visual>
        <collision>
            <origin xyz="0.0 0.0 0.0" rpy="0.0 0.0 0.0"/>
            <geometry>
                <cylinder radius="0.08" length="0.05"/>
            </geometry>
        </collision>
    </link>

    <!-- right wheel joint -->
    <joint name="joint_right_wheel" type="continuous">
        <origin xyz="-0.1 -0.175 0.0" rpy="0 1.5708 1.5708"/>
        <parent link="base_link"/>
        <child link="right_wheel"/>
        <axis xyz="0.0 0. 0.1"/>
        <limit lower="0.0" upper="0.0" effort="0.0" velocity="0.0"/>
    </joint>

    <!-- left wheel link -->

    <link name="left_wheel">
        <inertial>
            <origin xyz="0.0 0.0 0.0" rpy="0.0 0.0 0.0"/>
            <mass value="0.05"/>
            <inertia ixx="0.001" ixy="0.0" ixz="0.0" iyy="0.001" iyz="0.0" izz="0.001"/>
        </inertial>
        <visual name="">
            <origin xyz="0.0 0.0 0.0" rpy="0.0 0.0 0.0"/>
            <geometry>
                <cylinder radius="0.08" length="0.05"/>
            </geometry>
            <material name="">
                <color rgba="1.0 0.0 0.0 1.0"/>
                <texture filename=""/>
            </material>
        </visual>
        <collision>
            <origin xyz="0.0 0.0 0.0" rpy="0.0 0.0 0.0"/>
            <geometry>
                <cylinder radius="0.08" length="0.05"/>
            </geometry>
        </collision>
    </link>

    <!-- left wheel link -->
    <joint name="left_wheel_joint" type="continuous">
        <origin xyz="-0.1 0.175 0.0" rpy="0 1.5708 1.5708"/>
        <parent link="base_link"/>
        <child link="left_wheel"/>
        <axis xyz="0.0 0.0 1.0"/>
        <limit lower="0.0" upper="0.0" effort="0.0" velocity="0.0"/>
    </joint>

    <!-- caster wheel link -->
    <link name="caster_wheel_link">
        <inertial>
            <origin xyz="0.0 0.0 0.0" rpy="0.0 0.0 0.0"/>
            <mass value="0.01"/>
            <inertia ixx="0.0" ixy="0.0" ixz="0.0" iyy="0.0" iyz="0.0" izz="0.0"/>
        </inertial>
        <visual name="">
            <origin xyz="0.0 0.0 0.0" rpy="0.0 0.0 0.0"/>
            <geometry>
                <sphere radius="0.02"/>
            </geometry>
            <material name="">
                <color rgba="1.0 0.0 0.0 1.0"/>
                <texture filename=""/>
            </material>
        </visual>
        <collision>
            <origin xyz="0.0 0.0 0.0" rpy="0.0 0.0 0.0"/>
            <geometry>
                <sphere radius="0.02"/>
            </geometry>
        </collision>
    </link>

    <!-- caster_wheel_joint -->
    <joint name="caster_wheel_joint" type="continuous">
        <origin xyz="0.1 0.0 -0.06" rpy="0.0 0.0 0.0"/>
        <parent link="base_link"/>
        <child link="caster_wheel_link"/>
        <axis xyz="1.0 1.0 1.0"/>
        <limit lower="0.0" upper="0.0" effort="0.0" velocity="0.0"/>
    </joint>

    <!-- reference frame for the robot's base -->
    <link name="base_footprint">
    </link>

    <joint name="base_footprint_joint" type="fixed">
      <origin
        xyz="0.0 0.0 0.0"
        rpy="0 0 0" />
      <parent link ="base_footprint"/>
      <child link ="base_link"/>
    </joint>


    <gazebo>
      <plugin name="differential_drive_controller" filename="libgazebo_ros_diff_drive.so">

        <!-- Plugin update rate in Hz -->
        <updateRate>100</updateRate>

        <!-- Name of left joint, defaults to `left_joint` -->
        <leftJoint>left_wheel_joint</leftJoint>

        <!-- Name of right joint, defaults to `right_joint` -->
        <rightJoint>right_wheel_joint</rightJoint>

        <!-- The distance from the center of one wheel to the other, in meters, defaults to 0.34 m -->
        <wheelSeparation>0.4</wheelSeparation>

        <!-- Diameter of the wheels, in meters, defaults to 0.15 m -->
        <wheelDiameter>0.16</wheelDiameter>

        <!-- Wheel acceleration, in rad/s^2, defaults to 0.0 rad/s^2 -->
        <wheelAcceleration>0.5</wheelAcceleration>

        <!-- Maximum torque which the wheels can produce, in Nm, defaults to 5 Nm -->
        <wheelTorque>5</wheelTorque>

        <!-- ROS topic for receiving velocity commands -->
        <topicName>cmd_vel</topicName>

        <!-- Topic to receive geometry_msgs/Twist message commands, defaults to `cmd_vel` -->
        <commandTopic>cmd_vel</commandTopic>

        <!-- Topic to publish nav_msgs/Odometry messages, defaults to `odom` -->
        <odometryTopic>odom</odometryTopic>

        <!-- Odometry frame, defaults to `odom` -->
        <odometryFrame>odom</odometryFrame>

        <!-- Robot frame to calculate odometry from, defaults to `base_footprint` -->
        <robotBaseFrame>base_footprint</robotBaseFrame>

        <!-- Odometry source, 0 for ENCODER, 1 for WORLD, defaults to WORLD -->
        <odometrySource>1</odometrySource>

        <!-- Set to true to publish transforms for the wheel links, defaults to false -->
        <publishWheelTF>false</publishWheelTF>

        <!-- Set to true to publish transforms for the odometry, defaults to true -->
        <publishOdom>true</publishOdom>

        <!-- Set to true to publish sensor_msgs/JointState on /joint_states for the wheel joints, defaults to false -->
        <publishWheelJointState>false</publishWheelJointState>

        <!-- Set to true to swap right and left wheels, defaults to true -->
        <legacyMode>false</legacyMode>
      </plugin>
    </gazebo>


    <gazebo reference="left_wheel">
      <material>Gazebo/Red</material>
    </gazebo>
    <gazebo reference="right_wheel">
      <material>Gazebo/Red</material>
    </gazebo>
    <gazebo reference="caster_wheel">
      <material>Gazebo/Red</material>
    </gazebo>
    <gazebo reference="base_link">
      <material>Gazebo/Yellow</material>
    </gazebo>


    


    





    





















































</robot>